Workbook

Sheet Door2Door| Paylogic
A1: ADE Door-to-Door | Paylogic | 2 teams x 3 dagen (di 13 t/m do 15 oktober)
A2: Start / eind | B2: Amsterdam Centraal | C2: Start 09:30 | D2: Uiterlijk circa 17:30
A3: Bezoekduur | B3: 20 minuten | C3: Lunch | D3: 30 minuten, ingepland
A4: Routeplanning | B4: Indicatief: rijtijden handmatig geschat; geen live Maps-tijden
A5: Let op | B5: Dinsdag zit Friso van 12:45 tot 14:45 op kantoor (De Ruijterkade 113); de pauze van Friso + Thierry valt in dat blok. Milo rijdt dinsdag mee met Yasmijn + Steven, Cecil woensdag met Friso + Thierry (Ahoy-dag).
A6: Legenda | C6: Verschoven naar Yasmijn + Steven (was Friso + Thierry) | D6: Overgenomen van andere leadowner | E6: Te laat (na 17:30 terug / na 12:45 op kantoor) | F6: Blauwe tekst = invoer (vertrek kantoor)
A8: Team | B8: Dag | C8: Leads | D8: Eigen leads | E8: Overgenomen | F8: Rijtijd (min) | G8: Bezoektijd (min) | H8: Lunch (min) | I8: Terug ca. | J8: Binnen 17:30?
A9: Yasmijn + Steven + Milo | B9: Dinsdag | C9: =COUNT(B20:B27) -> 8 | D9: =COUNTIF(J20:J27,"Eigen lead*") -> 4 | E9: =COUNTIF(J20:J27,"Overgenomen*") -> 4 | F9: =SUM(G20:G28) -> 280 | G9: =C9*20 -> 160 | H9: 30 | I9: =H28 -> 0.72222222 | J9: =IF(I9<=TIME(17,30,0),"JA","NEE") -> JA
A10: Yasmijn + Steven | B10: Woensdag | C10: =COUNT(B47:B52) -> 6 | D10: =COUNTIF(J47:J52,"Eigen lead*") -> 6 | E10: =COUNTIF(J47:J52,"Overgenomen*") -> 0 | F10: =SUM(G47:G53) -> 330 | G10: =C10*20 -> 120 | H10: 30 | I10: =H53 -> 0.72916667 | J10: =IF(I10<=TIME(17,30,0),"JA","NEE") -> JA
A11: Yasmijn + Steven | B11: Donderdag | C11: =COUNT(B69:B72) -> 4 | D11: =COUNTIF(J69:J72,"Eigen lead*") -> 3 | E11: =COUNTIF(J69:J72,"Overgenomen*") -> 1 | F11: =SUM(G69:G73) -> 339 | G11: =C11*20 -> 80 | H11: 30 | I11: =H73 -> 0.70763889 | J11: =IF(I11<=TIME(17,30,0),"JA","NEE") -> JA
A12: Friso + Thierry | B12: Dinsdag | C12: =COUNT(B31:B40) -> 9 | D12: =COUNTIF(J31:J40,"Eigen lead*") -> 7 | E12: =COUNTIF(J31:J40,"Overgenomen*") -> 2 | F12: =SUM(G31:G41) -> 132 | G12: =C12*20 -> 180 | H12: 0 | I12: =H41 -> 0.70972222 | J12: =IF(I12<=TIME(17,30,0),"JA","NEE") -> JA
A13: Friso + Thierry + Cecil | B13: Woensdag | C13: =COUNT(B56:B62) -> 7 | D13: =COUNTIF(J56:J62,"Eigen lead*") -> 6 | E13: =COUNTIF(J56:J62,"Overgenomen*") -> 1 | F13: =SUM(G56:G63) -> 286 | G13: =C13*20 -> 140 | H13: 30 | I13: =H63 -> 0.7125 | J13: =IF(I13<=TIME(17,30,0),"JA","NEE") -> JA
A14: Friso + Thierry | B14: Donderdag | C14: =COUNT(B76:B81) -> 6 | D14: =COUNTIF(J76:J81,"Eigen lead*") -> 6 | E14: =COUNTIF(J76:J81,"Overgenomen*") -> 0 | F14: =SUM(G76:G82) -> 172 | G14: =C14*20 -> 120 | H14: 30 | I14: =H82 -> 0.61944444 | J14: =IF(I14<=TIME(17,30,0),"JA","NEE") -> JA
A15: Totaal | C15: =SUM(C9:C14) -> 40 | D15: =SUM(D9:D14) -> 32 | E15: =SUM(E9:E14) -> 8 | F15: =SUM(F9:F14) -> 1539 | G15: =SUM(G9:G14) -> 800
A17: DAG 1 | DINSDAG 13 OKTOBER | VERTREK 09:30 | 20 MINUTEN PER LEAD + 30 MIN LUNCH
A18: Team | B18: Stop | C18: Lead | D18: Leadowner | E18: Adres | F18: Plaats | G18: Rijtijd vanaf vorig (min) | H18: Aankomst | I18: Vertrek | J18: Opmerking | K18: Google Maps
A19: Yasmijn + Steven + Milo | B19: START | C19: Amsterdam Centraal | E19: Stationsplein, Amsterdam | F19: Amsterdam | G19: 0 | H19: 0.39583333 | I19: 0.39583333 | J19: Per auto; rijtijden indicatief | Milo rijdt mee
A20: Yasmijn + Steven + Milo | B20: 1 | C20: Intercell/ AFP | D20: Yasmijn | E20: Rokin 54 | 1012KV | F20: Amsterdam | G20: 11 | H20: =I19+G20/1440+0/1440 -> 0.40347222 | I20: =H20+20/1440 -> 0.41736111 | J20: Eigen lead | K20: Open adres
A21: Yasmijn + Steven + Milo | B21: 2 | C21: Jaarbeurs | D21: Thierry | E21: Jaarbeursplein 6 | 3521 AL | F21: Utrecht | G21: 39 | H21: =I20+G21/1440+0/1440 -> 0.44444444 | I21: =H21+20/1440 -> 0.45833333 | J21: Overgenomen van Thierry | K21: Open adres
A22: Yasmijn + Steven + Milo | B22: 3 | C22: Elevation Events | D22: Yasmijn | E22: Leidseweg 125 | 3533 HC | F22: Utrecht | G22: 5 | H22: =I21+G22/1440+0/1440 -> 0.46180556 | I22: =H22+20/1440 -> 0.47569444 | J22: Eigen lead | K22: Open adres
A23: Yasmijn + Steven + Milo | B23: 4 | C23: Studio Linksvoor | D23: Yasmijn | E23: De Kolk 13 | 6541 AV | F23: Nijmegen | G23: 63 | H23: =I22+G23/1440+0/1440 -> 0.51944444 | I23: =H23+20/1440 -> 0.53333333 | J23: Eigen lead | K23: Open adres
A24: Yasmijn + Steven + Milo | B24: 5 | C24: Classified Events [Urgent] | D24: Thierry | E24: Oude Molenweg 112 | 6533WN | F24: Nijmegen | G24: 14 | H24: =I23+G24/1440+30/1440 -> 0.56388889 | I24: =H24+20/1440 -> 0.57777778 | J24: Overgenomen van Thierry | K24: Open adres
A25: Yasmijn + Steven + Milo | B25: 6 | C25: Listen to Flow | D25: Thierry | E25: Roodwilligen 63 | 6903 TB | F25: Zevenaar | G25: 30 | H25: =I24+G25/1440+0/1440 -> 0.59861111 | I25: =H25+20/1440 -> 0.6125 | J25: Overgenomen van Thierry | K25: Open adres
A26: Yasmijn + Steven + Milo | B26: 7 | C26: ONA Groep | D26: Yasmijn | E26: Nijverheidsweg 16 | 3762 ER | F26: Soest | G26: 61 | H26: =I25+G26/1440+0/1440 -> 0.65486111 | I26: =H26+20/1440 -> 0.66875 | J26: Eigen lead | K26: Open adres
A27: Yasmijn + Steven + Milo | B27: 8 | C27: Reggae Lake | D27: Friso | E27: Zeeburgerdijk 19B | 1093SK | F27: Amsterdam | G27: 45 | H27: =I26+G27/1440+0/1440 -> 0.7 | I27: =H27+20/1440 -> 0.71388889 | J27: Overgenomen van Friso | K27: Open adres
A28: Yasmijn + Steven + Milo | B28: TERUG | C28: Amsterdam Centraal | E28: Stationsplein | F28: Amsterdam | G28: 12 | H28: =I27+G28/1440+0/1440 -> 0.72222222 | I28: =H28 -> 0.72222222 | J28: =IF(H28>TIME(17,30,0),"Inclusief lunch van 30 min | LET OP: na 17:30 terug, zie Aandachtspunten","Inclusief lunch van 30 min") -> Inclusief lunch van 30 min
A30: Friso + Thierry | B30: START | C30: Amsterdam Centraal | E30: Stationsplein, Amsterdam | F30: Amsterdam | G30: 0 | H30: 0.39583333 | I30: 0.39583333 | J30: Per auto; rijtijden indicatief
A31: Friso + Thierry | B31: 1 | C31: Making Waves | D31: Odin | E31: Doctor Jan van Breemenstraat 1 | 1056 Ab | F31: Amsterdam | G31: 20 | H31: =I30+G31/1440+0/1440 -> 0.40972222 | I31: =H31+20/1440 -> 0.42361111 | J31: Overgenomen van Odin | K31: Open adres
A32: Friso + Thierry | B32: 2 | C32: VBX | D32: Friso | E32: Krelis Louwenstraat 1 | 1055 KA | F32: Amsterdam | G32: 8 | H32: =I31+G32/1440+0/1440 -> 0.42916667 | I32: =H32+20/1440 -> 0.44305556 | J32: Eigen lead | K32: Open adres
A33: Friso + Thierry | B33: 3 | C33: Thuishaven | D33: Friso | E33: Contactweg 68 | 1014 BW | F33: Amsterdam | G33: 12 | H33: =I32+G33/1440+0/1440 -> 0.45138889 | I33: =H33+20/1440 -> 0.46527778 | J33: Eigen lead | K33: Open adres
A34: Friso + Thierry | B34: 4 | C34: IsBurning | D34: Friso | E34: Elementenstraat 25 | 1014 AS | F34: Amsterdam | G34: 10 | H34: =I33+G34/1440+0/1440 -> 0.47222222 | I34: =H34+20/1440 -> 0.48611111 | J34: Eigen lead | K34: Open adres
A35: Friso + Thierry | B35: 5 | C35: Chasing the Hihat | D35: Friso | E35: Danzigerbocht 21 | 1013 AM | F35: Amsterdam | G35: 12 | H35: =I34+G35/1440+0/1440 -> 0.49444444 | I35: =H35+20/1440 -> 0.50833333 | J35: Eigen lead | K35: Open adres
A36: Friso + Thierry | B36: KANTOOR | C36: Paylogic kantoor | Friso afzetten en ophalen | D36: Friso | E36: De Ruijterkade 113 | F36: Amsterdam | G36: 13 | H36: =I35+G36/1440 -> 0.51736111 | I36: 0.61458333 | J36: Meeting Friso 12:45-14:45, pauze in dit blok. Uitloop? Pas vertrektijd (blauw) aan. | K36: Open adres
A37: Friso + Thierry | B37: 6 | C37: Studio Wieman | D37: Friso | E37: Papaverweg 14 | 1032 KH | F37: Amsterdam | G37: 12 | H37: =I36+G37/1440+0/1440 -> 0.62291667 | I37: =H37+20/1440 -> 0.63680556 | J37: Eigen lead | K37: Open adres
A38: Friso + Thierry | B38: 7 | C38: ingang / no clubs | D38: Friso | E38: Gedempt Hamerkanaal 86 | 1021 KR | F38: Amsterdam | G38: 8 | H38: =I37+G38/1440+0/1440 -> 0.64236111 | I38: =H38+20/1440 -> 0.65625 | J38: Eigen lead | K38: Open adres
A39: Friso + Thierry | B39: 8 | C39: A Venue | D39: Friso | E39: Keizersgracht 618 | 1017 ER | F39: Amsterdam | G39: 18 | H39: =I38+G39/1440+0/1440 -> 0.66875 | I39: =H39+20/1440 -> 0.68263889 | J39: Eigen lead | K39: Open adres
A40: Friso + Thierry | B40: 9 | C40: Melkweg | D40: Odin | E40: Lijnbaansgracht 234A | 1017 PH | F40: Amsterdam | G40: 5 | H40: =I39+G40/1440+0/1440 -> 0.68611111 | I40: =H40+20/1440 -> 0.7 | J40: Overgenomen van Odin | K40: Open adres
A41: Friso + Thierry | B41: TERUG | C41: Amsterdam Centraal | E41: Stationsplein | F41: Amsterdam | G41: 14 | H41: =I40+G41/1440+0/1440 -> 0.70972222 | I41: =H41 -> 0.70972222 | J41: =IF(H41>TIME(17,30,0),"Pauze tijdens meeting Friso | LET OP: na 17:30 terug, zie Aandachtspunten","Pauze tijdens meeting Friso") -> Pauze tijdens meeting Friso
A44: DAG 2 | WOENSDAG 14 OKTOBER | VERTREK 09:30 | 20 MINUTEN PER LEAD + 30 MIN LUNCH
A45: Team | B45: Stop | C45: Lead | D45: Leadowner | E45: Adres | F45: Plaats | G45: Rijtijd vanaf vorig (min) | H45: Aankomst | I45: Vertrek | J45: Opmerking | K45: Google Maps
...

Sheet Door2Door | Eventim (Light)
A1: Toekomst Muziek B.V. | B1: Bas
A2: Torpedotheater | B2: Bas
A3: Bijlmerbios Openluchtbioscoop | B3: Emiel
A4: Theater 't Kapelletje | B4: Bas
A5: Bloemencorso | B5: Bas
A6: Supper Club | B6: Bas

Sheet Leadlijst sheet. 
B2: ADE Door-to-Door | Leadoverzicht P-Logic
B3: Team en Dag komen automatisch uit het tabblad 'Planning 2 teams'. Poppodium Volt is weggelaten (dubbel met Volt).
B5: # | C5: Lead | D5: Leadowner | E5: Team | F5: Dag | H5: Legenda | I5: Leads | L5: # | M5: Lead | N5: Leadowner | O5: Team | P5: Dag
B6: 1 | C6: Paradigm | D6: Yasmijn | E6: Yasmijn + Steven | F6: 1 | H6: Yasmijn | I6: 15 | L6: 1 | M6: Paradigm | N6: Yasmijn | O6: Yasmijn + Steven | P6: =IFERROR(CHOOSE(COUNTIF('Door2Door| Paylogic'!$A$1:INDEX('Door2Door| Paylogic'!$A$1:$A$84,MATCH(M6,'Door2Door| Paylogic'!$C$1:$C$84,0)),"DAG *"),"Dinsdag","Woensdag","Donderdag"),"Niet ingepland") -> Woensdag
B7: 2 | C7: Kaleidoscope | D7: Yasmijn | E7: Yasmijn + Steven | F7: 1 | H7: Friso | I7: 19 | L7: 2 | M7: Kaleidoscope | N7: Yasmijn | O7: Yasmijn + Steven | P7: =IFERROR(CHOOSE(COUNTIF('Door2Door| Paylogic'!$A$1:INDEX('Door2Door| Paylogic'!$A$1:$A$84,MATCH(M7,'Door2Door| Paylogic'!$C$1:$C$84,0)),"DAG *"),"Dinsdag","Woensdag","Donderdag"),"Niet ingepland") -> Woensdag
B8: 3 | C8: ONA Groep | D8: Yasmijn | E8: Yasmijn + Steven | F8: 1 | H8: Thierry | I8: 7 | L8: 3 | M8: ONA Groep | N8: Yasmijn | O8: Yasmijn + Steven | P8: =IFERROR(CHOOSE(COUNTIF('Door2Door| Paylogic'!$A$1:INDEX('Door2Door| Paylogic'!$A$1:$A$84,MATCH(M8,'Door2Door| Paylogic'!$C$1:$C$84,0)),"DAG *"),"Dinsdag","Woensdag","Donderdag"),"Niet ingepland") -> Dinsdag
B9: 4 | C9: Reggae Lake | D9: Friso | E9: Yasmijn + Steven | F9: 1 | H9: Odin | I9: 2 | L9: 4 | M9: Reggae Lake | N9: Friso | O9: Yasmijn + Steven | P9: =IFERROR(CHOOSE(COUNTIF('Door2Door| Paylogic'!$A$1:INDEX('Door2Door| Paylogic'!$A$1:$A$84,MATCH(M9,'Door2Door| Paylogic'!$C$1:$C$84,0)),"DAG *"),"Dinsdag","Woensdag","Donderdag"),"Niet ingepland") -> Dinsdag | R9: Milo dinsdag
B10: 5 | C10: Listen to Flow | D10: Thierry | E10: Yasmijn + Steven | F10: 2 | H10: Totaal | I10: 43 | L10: 5 | M10: Listen to Flow | N10: Thierry | O10: Yasmijn + Steven | P10: =IFERROR(CHOOSE(COUNTIF('Door2Door| Paylogic'!$A$1:INDEX('Door2Door| Paylogic'!$A$1:$A$84,MATCH(M10,'Door2Door| Paylogic'!$C$1:$C$84,0)),"DAG *"),"Dinsdag","Woensdag","Donderdag"),"Niet ingepland") -> Dinsdag
B11: 6 | C11: Classified Events [Urgent] | D11: Thierry | E11: Yasmijn + Steven | F11: 2 | L11: 6 | M11: Classified Events [Urgent] | N11: Thierry | O11: Yasmijn + Steven | P11: =IFERROR(CHOOSE(COUNTIF('Door2Door| Paylogic'!$A$1:INDEX('Door2Door| Paylogic'!$A$1:$A$84,MATCH(M11,'Door2Door| Paylogic'!$C$1:$C$84,0)),"DAG *"),"Dinsdag","Woensdag","Donderdag"),"Niet ingepland") -> Dinsdag
B12: 7 | C12: Studio Linksvoor | D12: Yasmijn | E12: Yasmijn + Steven | F12: 2 | L12: 7 | M12: Studio Linksvoor | N12: Yasmijn | O12: Yasmijn + Steven | P12: =IFERROR(CHOOSE(COUNTIF('Door2Door| Paylogic'!$A$1:INDEX('Door2Door| Paylogic'!$A$1:$A$84,MATCH(M12,'Door2Door| Paylogic'!$C$1:$C$84,0)),"DAG *"),"Dinsdag","Woensdag","Donderdag"),"Niet ingepland") -> Dinsdag
B13: 8 | C13: Muze Misse | D13: Yasmijn | E13: Yasmijn + Steven | F13: 2 | L13: 8 | M13: Muze Misse | N13: Yasmijn | O13: Yasmijn + Steven | P13: =IFERROR(CHOOSE(COUNTIF('Door2Door| Paylogic'!$A$1:INDEX('Door2Door| Paylogic'!$A$1:$A$84,MATCH(M13,'Door2Door| Paylogic'!$C$1:$C$84,0)),"DAG *"),"Dinsdag","Woensdag","Donderdag"),"Niet ingepland") -> Donderdag
B14: 9 | C14: Par-t | D14: Yasmijn | E14: Yasmijn + Steven | F14: 2 | L14: 9 | M14: Par-t | N14: Yasmijn | O14: Yasmijn + Steven | P14: =IFERROR(CHOOSE(COUNTIF('Door2Door| Paylogic'!$A$1:INDEX('Door2Door| Paylogic'!$A$1:$A$84,MATCH(M14,'Door2Door| Paylogic'!$C$1:$C$84,0)),"DAG *"),"Dinsdag","Woensdag","Donderdag"),"Niet ingepland") -> Donderdag
B15: 10 | C15: Minority Events | D15: Yasmijn | E15: Yasmijn + Steven | F15: 2 | L15: 10 | M15: Minority Events | N15: Yasmijn | O15: Yasmijn + Steven | P15: =IFERROR(CHOOSE(COUNTIF('Door2Door| Paylogic'!$A$1:INDEX('Door2Door| Paylogic'!$A$1:$A$84,MATCH(M15,'Door2Door| Paylogic'!$C$1:$C$84,0)),"DAG *"),"Dinsdag","Woensdag","Donderdag"),"Niet ingepland") -> Donderdag
B16: 11 | C16: Volt | D16: Thierry | E16: Yasmijn + Steven | F16: 3 | L16: 11 | M16: Volt | N16: Thierry | O16: Yasmijn + Steven | P16: =IFERROR(CHOOSE(COUNTIF('Door2Door| Paylogic'!$A$1:INDEX('Door2Door| Paylogic'!$A$1:$A$84,MATCH(M16,'Door2Door| Paylogic'!$C$1:$C$84,0)),"DAG *"),"Dinsdag","Woensdag","Donderdag"),"Niet ingepland") -> Donderdag
B17: 12 | C17: Elevation Events | D17: Yasmijn | E17: Yasmijn + Steven | F17: 3 | L17: 12 | M17: Elevation Events | N17: Yasmijn | O17: Yasmijn + Steven | P17: =IFERROR(CHOOSE(COUNTIF('Door2Door| Paylogic'!$A$1:INDEX('Door2Door| Paylogic'!$A$1:$A$84,MATCH(M17,'Door2Door| Paylogic'!$C$1:$C$84,0)),"DAG *"),"Dinsdag","Woensdag","Donderdag"),"Niet ingepland") -> Dinsdag
B18: 13 | C18: Jaarbeurs | D18: Thierry | E18: Yasmijn + Steven | F18: 3 | L18: 13 | M18: Jaarbeurs | N18: Thierry | O18: Yasmijn + Steven | P18: =IFERROR(CHOOSE(COUNTIF('Door2Door| Paylogic'!$A$1:INDEX('Door2Door| Paylogic'!$A$1:$A$84,MATCH(M18,'Door2Door| Paylogic'!$C$1:$C$84,0)),"DAG *"),"Dinsdag","Woensdag","Donderdag"),"Niet ingepland") -> Dinsdag
B19: 14 | C19: Intercell/ AFP | D19: Yasmijn | E19: Yasmijn + Steven | F19: 3 | L19: 14 | M19: Intercell/ AFP | N19: Yasmijn | O19: Yasmijn + Steven | P19: =IFERROR(CHOOSE(COUNTIF('Door2Door| Paylogic'!$A$1:INDEX('Door2Door| Paylogic'!$A$1:$A$84,MATCH(M19,'Door2Door| Paylogic'!$C$1:$C$84,0)),"DAG *"),"Dinsdag","Woensdag","Donderdag"),"Niet ingepland") -> Dinsdag
B20: 15 | C20: Sunsplash | D20: Yasmijn | E20: Yasmijn + Steven | F20: 3 | L20: 15 | M20: Sunsplash | N20: Yasmijn | O20: Yasmijn + Steven | P20: =IFERROR(CHOOSE(COUNTIF('Door2Door| Paylogic'!$A$1:INDEX('Door2Door| Paylogic'!$A$1:$A$84,MATCH(M20,'Door2Door| Paylogic'!$C$1:$C$84,0)),"DAG *"),"Dinsdag","Woensdag","Donderdag"),"Niet ingepland") -> Woensdag
B21: 16 | C21: White House Scheveningen | D21: Thierry | E21: Friso + Thierry | F21: 1 | L21: 16 | M21: Paard | N21: Yasmijn | O21: Yasmijn + Steven | P21: =IFERROR(CHOOSE(COUNTIF('Door2Door| Paylogic'!$A$1:INDEX('Door2Door| Paylogic'!$A$1:$A$84,MATCH(M21,'Door2Door| Paylogic'!$C$1:$C$84,0)),"DAG *"),"Dinsdag","Woensdag","Donderdag"),"Niet ingepland") -> Niet ingepland
B22: 17 | C22: Paard | D22: Yasmijn | E22: Friso + Thierry | F22: 1 | L22: 17 | M22: Audio Obscura | N22: Friso | O22: Yasmijn + Steven | P22: =IFERROR(CHOOSE(COUNTIF('Door2Door| Paylogic'!$A$1:INDEX('Door2Door| Paylogic'!$A$1:$A$84,MATCH(M22,'Door2Door| Paylogic'!$C$1:$C$84,0)),"DAG *"),"Dinsdag","Woensdag","Donderdag"),"Niet ingepland") -> Niet ingepland
B23: 18 | C23: Cinema Culinair | D23: Yasmijn | E23: Friso + Thierry | F23: 1 | L23: 18 | M23: Gashouder | N23: Yasmijn | O23: Yasmijn + Steven | P23: =IFERROR(CHOOSE(COUNTIF('Door2Door| Paylogic'!$A$1:INDEX('Door2Door| Paylogic'!$A$1:$A$84,MATCH(M23,'Door2Door| Paylogic'!$C$1:$C$84,0)),"DAG *"),"Dinsdag","Woensdag","Donderdag"),"Niet ingepland") -> Woensdag
B24: 19 | C24: Give Soul | D24: Friso | E24: Friso + Thierry | F24: 1 | M24: Dfrnt Festival (Tapt) | N24: Yasmijn | O24: Yasmijn + Steven | P24: =IFERROR(CHOOSE(COUNTIF('Door2Door| Paylogic'!$A$1:INDEX('Door2Door| Paylogic'!$A$1:$A$84,MATCH(M24,'Door2Door| Paylogic'!$C$1:$C$84,0)),"DAG *"),"Dinsdag","Woensdag","Donderdag"),"Niet ingepland") -> Woensdag
B25: 20 | C25: CUBE | D25: Friso | E25: Friso + Thierry | F25: 1 | M25: Lofi | N25: Yasmijn | O25: Yasmijn + Steven | P25: =IFERROR(CHOOSE(COUNTIF('Door2Door| Paylogic'!$A$1:INDEX('Door2Door| Paylogic'!$A$1:$A$84,MATCH(M25,'Door2Door| Paylogic'!$C$1:$C$84,0)),"DAG *"),"Dinsdag","Woensdag","Donderdag"),"Niet ingepland") -> Woensdag
B26: 21 | C26: Ahoy Rotterdam | D26: Friso | E26: Friso + Thierry | F26: 1 | L26: 16 | M26: White House Scheveningen | N26: Thierry | O26: Friso + Thierry | P26: =IFERROR(CHOOSE(COUNTIF('Door2Door| Paylogic'!$A$1:INDEX('Door2Door| Paylogic'!$A$1:$A$84,MATCH(M26,'Door2Door| Paylogic'!$C$1:$C$84,0)),"DAG *"),"Dinsdag","Woensdag","Donderdag"),"Niet ingepland") -> Woensdag
B27: 22 | C27: The Zoo | D27: Thierry | E27: Friso + Thierry | F27: 1 | L27: 18 | M27: Cinema Culinair | N27: Yasmijn | O27: Friso + Thierry | P27: =IFERROR(CHOOSE(COUNTIF('Door2Door| Paylogic'!$A$1:INDEX('Door2Door| Paylogic'!$A$1:$A$84,MATCH(M27,'Door2Door| Paylogic'!$C$1:$C$84,0)),"DAG *"),"Dinsdag","Woensdag","Donderdag"),"Niet ingepland") -> Woensdag
B28: 23 | C28: Vivre Productions | D28: Friso | E28: Friso + Thierry | F28: 1 | L28: 19 | M28: Give Soul | N28: Friso | O28: Friso + Thierry | P28: =IFERROR(CHOOSE(COUNTIF('Door2Door| Paylogic'!$A$1:INDEX('Door2Door| Paylogic'!$A$1:$A$84,MATCH(M28,'Door2Door| Paylogic'!$C$1:$C$84,0)),"DAG *"),"Dinsdag","Woensdag","Donderdag"),"Niet ingepland") -> Woensdag
B29: 24 | C29: Studio Wieman | D29: Friso | E29: Friso + Thierry | F29: 2 | L29: 20 | M29: CUBE | N29: Friso | O29: Friso + Thierry | P29: =IFERROR(CHOOSE(COUNTIF('Door2Door| Paylogic'!$A$1:INDEX('Door2Door| Paylogic'!$A$1:$A$84,MATCH(M29,'Door2Door| Paylogic'!$C$1:$C$84,0)),"DAG *"),"Dinsdag","Woensdag","Donderdag"),"Niet ingepland") -> Woensdag
B30: 25 | C30: ingang / no clubs | D30: Friso | E30: Friso + Thierry | F30: 2 | L30: 21 | M30: Ahoy Rotterdam | N30: Friso | O30: Friso + Thierry | P30: =IFERROR(CHOOSE(COUNTIF('Door2Door| Paylogic'!$A$1:INDEX('Door2Door| Paylogic'!$A$1:$A$84,MATCH(M30,'Door2Door| Paylogic'!$C$1:$C$84,0)),"DAG *"),"Dinsdag","Woensdag","Donderdag"),"Niet ingepland") -> Woensdag
B31: 26 | C31: Melkweg | D31: Odin | E31: Friso + Thierry | F31: 2 | L31: 22 | M31: The Zoo | N31: Thierry | O31: Friso + Thierry | P31: =IFERROR(CHOOSE(COUNTIF('Door2Door| Paylogic'!$A$1:INDEX('Door2Door| Paylogic'!$A$1:$A$84,MATCH(M31,'Door2Door| Paylogic'!$C$1:$C$84,0)),"DAG *"),"Dinsdag","Woensdag","Donderdag"),"Niet ingepland") -> Woensdag | Q31: Cecil
B32: 27 | C32: A Venue | D32: Friso | E32: Friso + Thierry | F32: 2 | L32: 23 | M32: Vivre Productions | N32: Friso | O32: Friso + Thierry | P32: =IFERROR(CHOOSE(COUNTIF('Door2Door| Paylogic'!$A$1:INDEX('Door2Door| Paylogic'!$A$1:$A$84,MATCH(M32,'Door2Door| Paylogic'!$C$1:$C$84,0)),"DAG *"),"Dinsdag","Woensdag","Donderdag"),"Niet ingepland") -> Woensdag
B33: 28 | C33: Tropikali | D33: Friso | E33: Friso + Thierry | F33: 2 | L33: 24 | M33: Studio Wieman | N33: Friso | O33: Friso + Thierry | P33: =IFERROR(CHOOSE(COUNTIF('Door2Door| Paylogic'!$A$1:INDEX('Door2Door| Paylogic'!$A$1:$A$84,MATCH(M33,'Door2Door| Paylogic'!$C$1:$C$84,0)),"DAG *"),"Dinsdag","Woensdag","Donderdag"),"Niet ingepland") -> Dinsdag
B34: 29 | C34: Audio Obscura | D34: Friso | E34: Friso + Thierry | F34: 2 | L34: 25 | M34: ingang / no clubs | N34: Friso | O34: Friso + Thierry | P34: =IFERROR(CHOOSE(COUNTIF('Door2Door| Paylogic'!$A$1:INDEX('Door2Door| Paylogic'!$A$1:$A$84,MATCH(M34,'Door2Door| Paylogic'!$C$1:$C$84,0)),"DAG *"),"Dinsdag","Woensdag","Donderdag"),"Niet ingepland") -> Dinsdag
B35: 30 | C35: Loveland | D35: Friso | E35: Friso + Thierry | F35: 2 | L35: 26 | M35: Melkweg | N35: Odin | O35: Friso + Thierry | P35: =IFERROR(CHOOSE(COUNTIF('Door2Door| Paylogic'!$A$1:INDEX('Door2Door| Paylogic'!$A$1:$A$84,MATCH(M35,'Door2Door| Paylogic'!$C$1:$C$84,0)),"DAG *"),"Dinsdag","Woensdag","Donderdag"),"Niet ingepland") -> Dinsdag
B36: 31 | C36: 3X3 Basketbal | D36: Friso | E36: Friso + Thierry | F36: 2 | L36: 27 | M36: A Venue | N36: Friso | O36: Friso + Thierry | P36: =IFERROR(CHOOSE(COUNTIF('Door2Door| Paylogic'!$A$1:INDEX('Door2Door| Paylogic'!$A$1:$A$84,MATCH(M36,'Door2Door| Paylogic'!$C$1:$C$84,0)),"DAG *"),"Dinsdag","Woensdag","Donderdag"),"Niet ingepland") -> Dinsdag
B37: 32 | C37: Verknipt | D37: Friso | E37: Friso + Thierry | F37: 2 | L37: 28 | M37: Tropikali | N37: Friso | O37: Friso + Thierry | P37: =IFERROR(CHOOSE(COUNTIF('Door2Door| Paylogic'!$A$1:INDEX('Door2Door| Paylogic'!$A$1:$A$84,MATCH(M37,'Door2Door| Paylogic'!$C$1:$C$84,0)),"DAG *"),"Dinsdag","Woensdag","Donderdag"),"Niet ingepland") -> Donderdag
B38: 33 | C38: 8Ball | D38: Friso | E38: Friso + Thierry | F38: 2 | L38: 30 | M38: Loveland | N38: Friso | O38: Friso + Thierry | P38: =IFERROR(CHOOSE(COUNTIF('Door2Door| Paylogic'!$A$1:INDEX('Door2Door| Paylogic'!$A$1:$A$84,MATCH(M38,'Door2Door| Paylogic'!$C$1:$C$84,0)),"DAG *"),"Dinsdag","Woensdag","Donderdag"),"Niet ingepland") -> Donderdag
B39: 34 | C39: Chasing the Hihat | D39: Friso | E39: Friso + Thierry | F39: 3 | L39: 31 | M39: 3X3 Basketbal | N39: Friso | O39: Friso + Thierry | P39: =IFERROR(CHOOSE(COUNTIF('Door2Door| Paylogic'!$A$1:INDEX('Door2Door| Paylogic'!$A$1:$A$84,MATCH(M39,'Door2Door| Paylogic'!$C$1:$C$84,0)),"DAG *"),"Dinsdag","Woensdag","Donderdag"),"Niet ingepland") -> Donderdag
B40: 35 | C40: Gashouder | D40: Yasmijn | E40: Friso + Thierry | F40: 3 | L40: 32 | M40: Verknipt | N40: Friso | O40: Friso + Thierry | P40: =IFERROR(CHOOSE(COUNTIF('Door2Door| Paylogic'!$A$1:INDEX('Door2Door| Paylogic'!$A$1:$A$84,MATCH(M40,'Door2Door| Paylogic'!$C$1:$C$84,0)),"DAG *"),"Dinsdag","Woensdag","Donderdag"),"Niet ingepland") -> Donderdag
B41: 36 | C41: Thuishaven | D41: Friso | E41: Friso + Thierry | F41: 3 | L41: 33 | M41: 8Ball | N41: Friso | O41: Friso + Thierry | P41: =IFERROR(CHOOSE(COUNTIF('Door2Door| Paylogic'!$A$1:INDEX('Door2Door| Paylogic'!$A$1:$A$84,MATCH(M41,'Door2Door| Paylogic'!$C$1:$C$84,0)),"DAG *"),"Dinsdag","Woensdag","Donderdag"),"Niet ingepland") -> Donderdag
B42: 37 | C42: IsBurning | D42: Friso | E42: Friso + Thierry | F42: 3 | L42: 34 | M42: Chasing the Hihat | N42: Friso | O42: Friso + Thierry | P42: =IFERROR(CHOOSE(COUNTIF('Door2Door| Paylogic'!$A$1:INDEX('Door2Door| Paylogic'!$A$1:$A$84,MATCH(M42,'Door2Door| Paylogic'!$C$1:$C$84,0)),"DAG *"),"Dinsdag","Woensdag","Donderdag"),"Niet ingepland") -> Dinsdag
...
