Workbook

Sheet Leadoverzicht
A1: ADE Door-to-Door | Leadoverzicht P-Logic
A2: Team en Dag komen automatisch uit het tabblad 'Planning 2 teams'. Poppodium Volt is weggelaten (dubbel met Volt).
A4: # | B4: Lead | C4: Leadowner | D4: Team | E4: Dag | G4: Legenda | H4: Leads
A5: 1 | B5: Paradigm | C5: Yasmijn | D5: =IFERROR(INDEX('Planning 2 teams'!$A$1:$A$300,MATCH(B5,'Planning 2 teams'!$C$1:$C$300,0)),"Niet ingepland") -> Yasmijn + Steven | E5: =IFERROR(COUNTIF('Planning 2 teams'!$A$1:INDEX('Planning 2 teams'!$A$1:$A$300,MATCH(B5,'Planning 2 teams'!$C$1:$C$300,0)),"DAG *"),"") -> 1 | G5: Yasmijn | H5: =COUNTIF($C$5:$C$47,G5) -> 15
A6: 2 | B6: Kaleidoscope | C6: Yasmijn | D6: =IFERROR(INDEX('Planning 2 teams'!$A$1:$A$300,MATCH(B6,'Planning 2 teams'!$C$1:$C$300,0)),"Niet ingepland") -> Yasmijn + Steven | E6: =IFERROR(COUNTIF('Planning 2 teams'!$A$1:INDEX('Planning 2 teams'!$A$1:$A$300,MATCH(B6,'Planning 2 teams'!$C$1:$C$300,0)),"DAG *"),"") -> 1 | G6: Friso | H6: =COUNTIF($C$5:$C$47,G6) -> 19
A7: 3 | B7: ONA Groep | C7: Yasmijn | D7: =IFERROR(INDEX('Planning 2 teams'!$A$1:$A$300,MATCH(B7,'Planning 2 teams'!$C$1:$C$300,0)),"Niet ingepland") -> Yasmijn + Steven | E7: =IFERROR(COUNTIF('Planning 2 teams'!$A$1:INDEX('Planning 2 teams'!$A$1:$A$300,MATCH(B7,'Planning 2 teams'!$C$1:$C$300,0)),"DAG *"),"") -> 1 | G7: Thierry | H7: =COUNTIF($C$5:$C$47,G7) -> 7
A8: 4 | B8: Reggae Lake | C8: Friso | D8: =IFERROR(INDEX('Planning 2 teams'!$A$1:$A$300,MATCH(B8,'Planning 2 teams'!$C$1:$C$300,0)),"Niet ingepland") -> Yasmijn + Steven | E8: =IFERROR(COUNTIF('Planning 2 teams'!$A$1:INDEX('Planning 2 teams'!$A$1:$A$300,MATCH(B8,'Planning 2 teams'!$C$1:$C$300,0)),"DAG *"),"") -> 1 | G8: Odin | H8: =COUNTIF($C$5:$C$47,G8) -> 2
A9: 5 | B9: Listen to Flow | C9: Thierry | D9: =IFERROR(INDEX('Planning 2 teams'!$A$1:$A$300,MATCH(B9,'Planning 2 teams'!$C$1:$C$300,0)),"Niet ingepland") -> Yasmijn + Steven | E9: =IFERROR(COUNTIF('Planning 2 teams'!$A$1:INDEX('Planning 2 teams'!$A$1:$A$300,MATCH(B9,'Planning 2 teams'!$C$1:$C$300,0)),"DAG *"),"") -> 2 | G9: Totaal | H9: =SUM(H5:H8) -> 43
A10: 6 | B10: Classified Events [Urgent] | C10: Thierry | D10: =IFERROR(INDEX('Planning 2 teams'!$A$1:$A$300,MATCH(B10,'Planning 2 teams'!$C$1:$C$300,0)),"Niet ingepland") -> Yasmijn + Steven | E10: =IFERROR(COUNTIF('Planning 2 teams'!$A$1:INDEX('Planning 2 teams'!$A$1:$A$300,MATCH(B10,'Planning 2 teams'!$C$1:$C$300,0)),"DAG *"),"") -> 2
A11: 7 | B11: Studio Linksvoor | C11: Yasmijn | D11: =IFERROR(INDEX('Planning 2 teams'!$A$1:$A$300,MATCH(B11,'Planning 2 teams'!$C$1:$C$300,0)),"Niet ingepland") -> Yasmijn + Steven | E11: =IFERROR(COUNTIF('Planning 2 teams'!$A$1:INDEX('Planning 2 teams'!$A$1:$A$300,MATCH(B11,'Planning 2 teams'!$C$1:$C$300,0)),"DAG *"),"") -> 2
A12: 8 | B12: Muze Misse | C12: Yasmijn | D12: =IFERROR(INDEX('Planning 2 teams'!$A$1:$A$300,MATCH(B12,'Planning 2 teams'!$C$1:$C$300,0)),"Niet ingepland") -> Yasmijn + Steven | E12: =IFERROR(COUNTIF('Planning 2 teams'!$A$1:INDEX('Planning 2 teams'!$A$1:$A$300,MATCH(B12,'Planning 2 teams'!$C$1:$C$300,0)),"DAG *"),"") -> 2
A13: 9 | B13: Par-t | C13: Yasmijn | D13: =IFERROR(INDEX('Planning 2 teams'!$A$1:$A$300,MATCH(B13,'Planning 2 teams'!$C$1:$C$300,0)),"Niet ingepland") -> Yasmijn + Steven | E13: =IFERROR(COUNTIF('Planning 2 teams'!$A$1:INDEX('Planning 2 teams'!$A$1:$A$300,MATCH(B13,'Planning 2 teams'!$C$1:$C$300,0)),"DAG *"),"") -> 2
A14: 10 | B14: Minority Events | C14: Yasmijn | D14: =IFERROR(INDEX('Planning 2 teams'!$A$1:$A$300,MATCH(B14,'Planning 2 teams'!$C$1:$C$300,0)),"Niet ingepland") -> Yasmijn + Steven | E14: =IFERROR(COUNTIF('Planning 2 teams'!$A$1:INDEX('Planning 2 teams'!$A$1:$A$300,MATCH(B14,'Planning 2 teams'!$C$1:$C$300,0)),"DAG *"),"") -> 2
A15: 11 | B15: Volt | C15: Thierry | D15: =IFERROR(INDEX('Planning 2 teams'!$A$1:$A$300,MATCH(B15,'Planning 2 teams'!$C$1:$C$300,0)),"Niet ingepland") -> Yasmijn + Steven | E15: =IFERROR(COUNTIF('Planning 2 teams'!$A$1:INDEX('Planning 2 teams'!$A$1:$A$300,MATCH(B15,'Planning 2 teams'!$C$1:$C$300,0)),"DAG *"),"") -> 3
A16: 12 | B16: Elevation Events | C16: Yasmijn | D16: =IFERROR(INDEX('Planning 2 teams'!$A$1:$A$300,MATCH(B16,'Planning 2 teams'!$C$1:$C$300,0)),"Niet ingepland") -> Yasmijn + Steven | E16: =IFERROR(COUNTIF('Planning 2 teams'!$A$1:INDEX('Planning 2 teams'!$A$1:$A$300,MATCH(B16,'Planning 2 teams'!$C$1:$C$300,0)),"DAG *"),"") -> 3
A17: 13 | B17: Jaarbeurs | C17: Thierry | D17: =IFERROR(INDEX('Planning 2 teams'!$A$1:$A$300,MATCH(B17,'Planning 2 teams'!$C$1:$C$300,0)),"Niet ingepland") -> Yasmijn + Steven | E17: =IFERROR(COUNTIF('Planning 2 teams'!$A$1:INDEX('Planning 2 teams'!$A$1:$A$300,MATCH(B17,'Planning 2 teams'!$C$1:$C$300,0)),"DAG *"),"") -> 3
A18: 14 | B18: Intercell/ AFP | C18: Yasmijn | D18: =IFERROR(INDEX('Planning 2 teams'!$A$1:$A$300,MATCH(B18,'Planning 2 teams'!$C$1:$C$300,0)),"Niet ingepland") -> Yasmijn + Steven | E18: =IFERROR(COUNTIF('Planning 2 teams'!$A$1:INDEX('Planning 2 teams'!$A$1:$A$300,MATCH(B18,'Planning 2 teams'!$C$1:$C$300,0)),"DAG *"),"") -> 3
A19: 15 | B19: Sunsplash | C19: Yasmijn | D19: =IFERROR(INDEX('Planning 2 teams'!$A$1:$A$300,MATCH(B19,'Planning 2 teams'!$C$1:$C$300,0)),"Niet ingepland") -> Yasmijn + Steven | E19: =IFERROR(COUNTIF('Planning 2 teams'!$A$1:INDEX('Planning 2 teams'!$A$1:$A$300,MATCH(B19,'Planning 2 teams'!$C$1:$C$300,0)),"DAG *"),"") -> 3
A20: 16 | B20: White House Scheveningen | C20: Thierry | D20: =IFERROR(INDEX('Planning 2 teams'!$A$1:$A$300,MATCH(B20,'Planning 2 teams'!$C$1:$C$300,0)),"Niet ingepland") -> Friso + Thierry | E20: =IFERROR(COUNTIF('Planning 2 teams'!$A$1:INDEX('Planning 2 teams'!$A$1:$A$300,MATCH(B20,'Planning 2 teams'!$C$1:$C$300,0)),"DAG *"),"") -> 1
A21: 17 | B21: Paard | C21: Yasmijn | D21: =IFERROR(INDEX('Planning 2 teams'!$A$1:$A$300,MATCH(B21,'Planning 2 teams'!$C$1:$C$300,0)),"Niet ingepland") -> Friso + Thierry | E21: =IFERROR(COUNTIF('Planning 2 teams'!$A$1:INDEX('Planning 2 teams'!$A$1:$A$300,MATCH(B21,'Planning 2 teams'!$C$1:$C$300,0)),"DAG *"),"") -> 1
... A47: 43 | B47: Woodstock | C47: Thierry | D47: =IFERROR(INDEX('Planning 2 teams'!$A$1:$A$300,MATCH(B47,'Planning 2 teams'!$C$1:$C$300,0)),"Niet ingepland") -> Friso + Thierry | E47: =IFERROR(COUNTIF('Planning 2 teams'!$A$1:INDEX('Planning 2 teams'!$A$1:$A$300,MATCH(B47,'Planning 2 teams'!$C$1:$C$300,0)),"DAG *"),"") -> 3

Sheet Planning 2 teams
A1: ADE Door-to-Door | 2 teams x 3 dagen | herverdeling zonder Emiel + Bas
A2: Start / eind | B2: Amsterdam Centraal | C2: Start 09:30 | D2: Uiterlijk circa 17:30
A3: Bezoekduur | B3: 20 minuten | C3: Lunch | D3: 30 minuten, ingepland
A4: Routeplanning | B4: Indicatief: rijtijden handmatig geschat; geen live Maps-tijden
A5: Let op | B5: Emiel + Bas doen alleen hun eigen leads (zie Sheet1) en staan niet in deze planning. Hun overgenomen leads van andere leadowners zijn verdeeld over de twee teams hieronder.
A6: Legenda | C6: Nieuw toegevoegd (was Emiel + Bas) | D6: Overgenomen van andere leadowner | E6: Na 17:30 terug: oplossing nodig
A8: Team | B8: Dag | C8: Leads | D8: Eigen leads | E8: Nieuw toegevoegd | F8: Rijtijd (min) | G8: Bezoektijd (min) | H8: Lunch (min) | I8: Terug ca. | J8: Binnen 17:30?
A9: Yasmijn + Steven | B9: 1 | C9: =COUNT(B20:B23) -> 4 | D9: =COUNTIF(J20:J23,"Eigen lead*") -> 3 | E9: =COUNTIF(J20:J23,"*was Emiel + Bas*") -> 1 | F9: =SUM(G20:G24) -> 319 | G9: =C9*20 -> 80 | H9: 30 | I9: =H24 -> 0.69375 | J9: =IF(I9<=TIME(17,30,0),"JA","NEE") -> JA
A10: Yasmijn + Steven | B10: 2 | C10: =COUNT(B41:B46) -> 6 | D10: =COUNTIF(J41:J46,"Eigen lead*") -> 4 | E10: =COUNTIF(J41:J46,"*was Emiel + Bas*") -> 1 | F10: =SUM(G41:G47) -> 356 | G10: =C10*20 -> 120 | H10: 30 | I10: =H47 -> 0.74722222 | J10: =IF(I10<=TIME(17,30,0),"JA","NEE") -> NEE
A11: Yasmijn + Steven | B11: 3 | C11: =COUNT(B66:B70) -> 5 | D11: =COUNTIF(J66:J70,"Eigen lead*") -> 3 | E11: =COUNTIF(J66:J70,"*was Emiel + Bas*") -> 0 | F11: =SUM(G66:G71) -> 328 | G11: =C11*20 -> 100 | H11: 30 | I11: =H71 -> 0.71388889 | J11: =IF(I11<=TIME(17,30,0),"JA","NEE") -> JA
A12: Friso + Thierry | B12: 1 | C12: =COUNT(B27:B34) -> 8 | D12: =COUNTIF(J27:J34,"Eigen lead*") -> 6 | E12: =COUNTIF(J27:J34,"*was Emiel + Bas*") -> 3 | F12: =SUM(G27:G35) -> 295 | G12: =C12*20 -> 160 | H12: 30 | I12: =H35 -> 0.73263889 | J12: =IF(I12<=TIME(17,30,0),"JA","NEE") -> NEE
A13: Friso + Thierry | B13: 2 | C13: =COUNT(B50:B59) -> 10 | D13: =COUNTIF(J50:J59,"Eigen lead*") -> 9 | E13: =COUNTIF(J50:J59,"*was Emiel + Bas*") -> 3 | F13: =SUM(G50:G60) -> 190 | G13: =C13*20 -> 200 | H13: 30 | I13: =H60 -> 0.6875 | J13: =IF(I13<=TIME(17,30,0),"JA","NEE") -> JA
A14: Friso + Thierry | B14: 3 | C14: =COUNT(B74:B83) -> 10 | D14: =COUNTIF(J74:J83,"Eigen lead*") -> 6 | E14: =COUNTIF(J74:J83,"*was Emiel + Bas*") -> 4 | F14: =SUM(G74:G84) -> 179 | G14: =C14*20 -> 200 | H14: 30 | I14: =H84 -> 0.67986111 | J14: =IF(I14<=TIME(17,30,0),"JA","NEE") -> JA
A15: Totaal | C15: =SUM(C9:C14) -> 43 | D15: =SUM(D9:D14) -> 31 | E15: =SUM(E9:E14) -> 12 | F15: =SUM(F9:F14) -> 1667 | G15: =SUM(G9:G14) -> 860
A17: DAG 1 | VERTREK 09:30 | 20 MINUTEN PER LEAD + 30 MIN LUNCH
A18: Team | B18: Stop | C18: Lead | D18: Leadowner | E18: Adres | F18: Plaats | G18: Rijtijd vanaf vorig (min) | H18: Aankomst | I18: Vertrek | J18: Opmerking | K18: Google Maps
A19: Yasmijn + Steven | B19: START | C19: Amsterdam Centraal | E19: Stationsplein, Amsterdam | F19: Amsterdam | G19: 0 | H19: 0.39583333 | I19: 0.39583333 | J19: Per auto; rijtijden indicatief
A20: Yasmijn + Steven | B20: 1 | C20: Paradigm | D20: Yasmijn | E20: Energieweg 10 | 9743 AN | F20: Groningen | G20: 130 | H20: =I19+G20/1440+0/1440 -> 0.48611111 | I20: =H20+20/1440 -> 0.5 | J20: Eigen lead | K20: Open adres
A21: Yasmijn + Steven | B21: 2 | C21: Kaleidoscope | D21: Yasmijn | E21: Helsinkistraat 6 | 9723 BD | F21: Groningen | G21: 17 | H21: =I20+G21/1440+0/1440 -> 0.51180556 | I21: =H21+20/1440 -> 0.52569444 | J21: Eigen lead | K21: Open adres
A22: Yasmijn + Steven | B22: 3 | C22: ONA Groep | D22: Yasmijn | E22: Nijverheidsweg 16 | 3762 ER | F22: Soest | G22: 115 | H22: =I21+G22/1440+0/1440 -> 0.60555556 | I22: =H22+20/1440 -> 0.61944444 | J22: Eigen lead | K22: Open adres
A23: Yasmijn + Steven | B23: 4 | C23: Reggae Lake | D23: Friso | E23: Zeeburgerdijk 19B | 1093SK | F23: Amsterdam | G23: 45 | H23: =I22+G23/1440+0/1440 -> 0.65069444 | I23: =H23+20/1440 -> 0.66458333 | J23: Overgenomen van Friso (was Emiel + Bas, dag 1) | K23: Open adres
A24: Yasmijn + Steven | B24: TERUG | C24: Amsterdam Centraal | E24: Stationsplein | F24: Amsterdam | G24: 12 | H24: =I23+G24/1440+30/1440 -> 0.69375 | I24: =H24 -> 0.69375 | J24: =IF(H24>TIME(17,30,0),"Inclusief lunch van 30 min | LET OP: na 17:30 terug, zie Aandachtspunten","Inclusief lunch van 30 min") -> Inclusief lunch van 30 min
A26: Friso + Thierry | B26: START | C26: Amsterdam Centraal | E26: Stationsplein, Amsterdam | F26: Amsterdam | G26: 0 | H26: 0.39583333 | I26: 0.39583333 | J26: Per auto; rijtijden indicatief
A27: Friso + Thierry | B27: 1 | C27: White House Scheveningen | D27: Thierry | E27: Strandweg 180 | 2586 JM | F27: Den Haag | G27: 93 | H27: =I26+G27/1440+0/1440 -> 0.46041667 | I27: =H27+20/1440 -> 0.47430556 | J27: Eigen lead | K27: Open adres
A28: Friso + Thierry | B28: 2 | C28: Paard | D28: Yasmijn | E28: Prinsegracht 12 | 2512 GA | F28: Den Haag | G28: 19 | H28: =I27+G28/1440+0/1440 -> 0.4875 | I28: =H28+20/1440 -> 0.50138889 | J28: Overgenomen van Yasmijn | K28: Open adres
A29: Friso + Thierry | B29: 3 | C29: Cinema Culinair | D29: Yasmijn | E29: Keilestraat 9F | 3029 BP | F29: Rotterdam | G29: 30 | H29: =I28+G29/1440+0/1440 -> 0.52222222 | I29: =H29+20/1440 -> 0.53611111 | J29: Overgenomen van Yasmijn (was Emiel + Bas, dag 2) | K29: Open adres
A30: Friso + Thierry | B30: 4 | C30: Give Soul | D30: Friso | E30: Eendrachtsweg 42 | 3012 LD | F30: Rotterdam | G30: 10 | H30: =I29+G30/1440+0/1440 -> 0.54305556 | I30: =H30+20/1440 -> 0.55694444 | J30: Eigen lead | K30: Open adres
A31: Friso + Thierry | B31: 5 | C31: CUBE | D31: Friso | E31: Slepersvest 1 | 3011 ML | F31: Rotterdam | G31: 7 | H31: =I30+G31/1440+30/1440 -> 0.58263889 | I31: =H31+20/1440 -> 0.59652778 | J31: Eigen lead (was Emiel + Bas, dag 2) | K31: Open adres
A32: Friso + Thierry | B32: 6 | C32: Ahoy Rotterdam | D32: Friso | E32: Ahoyweg 10 | 3084 BD | F32: Rotterdam | G32: 12 | H32: =I31+G32/1440+0/1440 -> 0.60486111 | I32: =H32+20/1440 -> 0.61875 | J32: Eigen lead | K32: Open adres
A33: Friso + Thierry | B33: 7 | C33: The Zoo | D33: Thierry | E33: Boonsweg 10 | 274 LH | F33: Heinenoord | G33: 18 | H33: =I32+G33/1440+0/1440 -> 0.63125 | I33: =H33+20/1440 -> 0.64513889 | J33: Eigen lead (was Emiel + Bas, dag 2) | K33: Open adres
A34: Friso + Thierry | B34: 8 | C34: Vivre Productions | D34: Friso | E34: Hoofdweg-Noord 9K | 2913 LB | F34: Nieuwekerk ad IJssel | G34: 27 | H34: =I33+G34/1440+0/1440 -> 0.66388889 | I34: =H34+20/1440 -> 0.67777778 | J34: Eigen lead | K34: Open adres
A35: Friso + Thierry | B35: TERUG | C35: Amsterdam Centraal | E35: Stationsplein | F35: Amsterdam | G35: 79 | H35: =I34+G35/1440+0/1440 -> 0.73263889 | I35: =H35 -> 0.73263889 | J35: =IF(H35>TIME(17,30,0),"Inclusief lunch van 30 min | LET OP: na 17:30 terug, zie Aandachtspunten","Inclusief lunch van 30 min") -> Inclusief lunch van 30 min | LET OP: na 17:30 terug, zie Aandachtspunten
A38: DAG 2 | VERTREK 09:30 | 20 MINUTEN PER LEAD + 30 MIN LUNCH
A39: Team | B39: Stop | C39: Lead | D39: Leadowner | E39: Adres | F39: Plaats | G39: Rijtijd vanaf vorig (min) | H39: Aankomst | I39: Vertrek | J39: Opmerking | K39: Google Maps
A40: Yasmijn + Steven | B40: START | C40: Amsterdam Centraal | E40: Stationsplein, Amsterdam | F40: Amsterdam | G40: 0 | H40: 0.39583333 | I40: 0.39583333 | J40: Per auto; rijtijden indicatief
A41: Yasmijn + Steven | B41: 1 | C41: Listen to Flow | D41: Thierry | E41: Roodwilligen 63 | 6903 TB | F41: Zevenaar | G41: 100 | H41: =I40+G41/1440+0/1440 -> 0.46527778 | I41: =H41+20/1440 -> 0.47916667 | J41: Overgenomen van Thierry (was Emiel + Bas, dag 3) | K41: Open adres
A42: Yasmijn + Steven | B42: 2 | C42: Classified Events [Urgent] | D42: Thierry | E42: Oude Molenweg 112 | 6533WN | F42: Nijmegen | G42: 30 | H42: =I41+G42/1440+0/1440 -> 0.5 | I42: =H42+20/1440 -> 0.51388889 | J42: Overgenomen van Thierry | K42: Open adres
A43: Yasmijn + Steven | B43: 3 | C43: Studio Linksvoor | D43: Yasmijn | E43: De Kolk 13 | 6541 AV | F43: Nijmegen | G43: 14 | H43: =I42+G43/1440+0/1440 -> 0.52361111 | I43: =H43+20/1440 -> 0.5375 | J43: Eigen lead | K43: Open adres
A44: Yasmijn + Steven | B44: 4 | C44: Muze Misse | D44: Yasmijn | E44: Sint Sebastiaanstraat 57 | 5341 LG | F44: Oss | G44: 35 | H44: =I43+G44/1440+0/1440 -> 0.56180556 | I44: =H44+20/1440 -> 0.57569444 | J44: Eigen lead | K44: Open adres
A45: Yasmijn + Steven | B45: 5 | C45: Par-t | D45: Yasmijn | E45: Bussele 17 | 5469 DT | F45: Erp/Veghel | G45: 25 | H45: =I44+G45/1440+30/1440 -> 0.61388889 | I45: =H45+20/1440 -> 0.62777778 | J45: Eigen lead | K45: Open adres
...

Sheet Overzicht
A1: ADE Door-to-Door | 3 teams x 3 dagen
A2: Start / eind | B2: Amsterdam Centraal | C2: Start 09:30 | D2: Uiterlijk circa 17:30
A3: Bezoekduur | B3: 20 minuten | C3: Lunch | D3: 30 minuten, ingepland
A4: Routeplanning | B4: Indicatief: rijtijden handmatig geschat; geen live Maps-tijden
A5: Let op | B5: Uitgesloten: onbruikbare of ontbrekende afleveradressen
A7: Team | B7: Dag | C7: Leads | D7: Eigen leads | E7: Rijtijd (min) | F7: Bezoektijd (min) | G7: Lunch (min) | H7: Terug ca. | I7: Binnen 17:30?
A8: Emiel + Bas | B8: 1 | C8: 7 | D8: 3 | E8: 133 | F8: 140 | G8: 30 | H8: ='Dag 1'!H11 -> 0.60625 | I8: =IF(H8<=TIME(17,30,0),"JA","NEE") -> JA
A9: Emiel + Bas | B9: 2 | C9: 4 | D9: 1 | E9: 224 | F9: 80 | G9: 30 | H9: ='Dag 2'!H9 -> 0.7 | I9: =IF(H9<=TIME(17,30,0),"JA","NEE") -> JA
A10: Emiel + Bas | B10: 3 | C10: 4 | D10: 0 | E10: 95 | F10: 80 | G10: 30 | H10: ='Dag 3'!H9 -> 0.69722222 | I10: =IF(H10<=TIME(17,30,0),"JA","NEE") -> JA
A11: Yasmijn + Steven | B11: 1 | C11: 3 | D11: 3 | E11: 308 | F11: 60 | G11: 30 | H11: ='Dag 1'!H17 -> 0.67569444 | I11: =IF(H11<=TIME(17,30,0),"JA","NEE") -> JA
A12: Yasmijn + Steven | B12: 2 | C12: 5 | D12: 4 | E12: 318 | F12: 100 | G12: 30 | H12: ='Dag 2'!H17 -> 0.70694444 | I12: =IF(H12<=TIME(17,30,0),"JA","NEE") -> JA
A13: Yasmijn + Steven | B13: 3 | C13: 4 | D13: 4 | E13: 323 | F13: 80 | G13: 30 | H13: ='Dag 3'!H17 -> 0.71458333 | I13: =IF(H13<=TIME(17,30,0),"JA","NEE") -> JA
A14: Friso + Thierry | B14: 1 | C14: 5 | D14: 4 | E14: 263 | F14: 100 | G14: 30 | H14: ='Dag 1'!H25 -> 0.67569444 | I14: =IF(H14<=TIME(17,30,0),"JA","NEE") -> JA
A15: Friso + Thierry | B15: 2 | C15: 7 | D15: 7 | E15: 165 | F15: 140 | G15: 30 | H15: ='Dag 2'!H27 -> 0.62847222 | I15: =IF(H15<=TIME(17,30,0),"JA","NEE") -> JA
A16: Friso + Thierry | B16: 3 | C16: 6 | D16: 4 | E16: 148 | F16: 120 | G16: 30 | H16: ='Dag 3'!H26 -> 0.60277778 | I16: =IF(H16<=TIME(17,30,0),"JA","NEE") -> JA

Sheet Dag 1
A1: DAG 1 | VERTREK 09:30 | 20 MINUTEN PER LEAD + 30 MIN LUNCH
A2: Team | B2: Stop | C2: Lead | D2: Leadowner | E2: Adres | F2: Plaats | G2: Rijtijd vanaf vorig (min) | H2: Aankomst | I2: Vertrek | J2: Opmerking | K2: Google Maps
A3: Emiel + Bas | B3: START | C3: Amsterdam Centraal | E3: Stationsplein, Amsterdam | F3: Amsterdam | G3: 0 | H3: 0.39583333 | I3: 0.39583333 | J3: Per auto; rijtijden indicatief
A4: Emiel + Bas | B4: 1 | C4: Toekomst Muziek B.V. | D4: Bas | E4: Danzigerbocht 29 | 1013 AM | F4: Amsterdam | G4: 20 | H4: =I3+G4/1440+0/1440 -> 0.40972222 | I4: =H4+20/1440 -> 0.42361111 | J4: Eigen lead | K4: Open adres
A5: Emiel + Bas | B5: 2 | C5: Chasing the Hihat | D5: Friso | E5: Danzigerbocht 21 | 1013 AM | F5: Amsterdam | G5: 3 | H5: =I4+G5/1440+0/1440 -> 0.42569444 | I5: =H5+20/1440 -> 0.43958333 | J5: Overgenomen van Friso | K5: Open adres
A6: Emiel + Bas | B6: 3 | C6: Studio Wieman | D6: Friso | E6: Papaverweg 14 | 1032 KH | F6: Amsterdam | G6: 14 | H6: =I5+G6/1440+0/1440 -> 0.44930556 | I6: =H6+20/1440 -> 0.46319444 | J6: Overgenomen van Friso | K6: Open adres
A7: Emiel + Bas | B7: 4 | C7: ingang / no clubs | D7: Friso | E7: Gedempt Hamerkanaal 86 | 1021 KR | F7: Amsterdam | G7: 8 | H7: =I6+G7/1440+30/1440 -> 0.48958333 | I7: =H7+20/1440 -> 0.50347222 | J7: Overgenomen van Friso | K7: Open adres
A8: Emiel + Bas | B8: 5 | C8: Torpedotheater | D8: Bas | E8: St. Pieterspoortsteeg 33 | 1012 HM | F8: Amsterdam | G8: 18 | H8: =I7+G8/1440+0/1440 -> 0.51597222 | I8: =H8+20/1440 -> 0.52986111 | J8: Eigen lead | K8: Open adres
A9: Emiel + Bas | B9: 6 | C9: Reggae Lake | D9: Friso | E9: Zeeburgerdijk 19B | 1093SK | F9: Amsterdam | G9: 18 | H9: =I8+G9/1440+0/1440 -> 0.54236111 | I9: =H9+20/1440 -> 0.55625 | J9: Overgenomen van Friso | K9: Open adres
A10: Emiel + Bas | B10: 7 | C10: Bijlmerbios Openluchtbioscoop | D10: Emiel | E10: Kraaiennest 80 | 1104 CE | F10: Amsterdam | G10: 28 | H10: =I9+G10/1440+0/1440 -> 0.57569444 | I10: =H10+20/1440 -> 0.58958333 | J10: Eigen lead | K10: Open adres
A11: Emiel + Bas | B11: TERUG | C11: Amsterdam Centraal | E11: Stationsplein | F11: Amsterdam | G11: 24 | H11: =I10+G11/1440+0/1440 -> 0.60625 | I11: =H11 -> 0.60625 | J11: Inclusief lunch van 30 min
A13: Yasmijn + Steven | B13: START | C13: Amsterdam Centraal | E13: Stationsplein, Amsterdam | F13: Amsterdam | G13: 0 | H13: 0.39583333 | I13: 0.39583333 | J13: Per auto; rijtijden indicatief
A14: Yasmijn + Steven | B14: 1 | C14: Paradigm | D14: Yasmijn | E14: Energieweg 10 | 9743 AN | F14: Groningen | G14: 130 | H14: =I13+G14/1440+0/1440 -> 0.48611111 | I14: =H14+20/1440 -> 0.5 | J14: Eigen lead | K14: Open adres
A15: Yasmijn + Steven | B15: 2 | C15: Kaleidoscope | D15: Yasmijn | E15: Helsinkistraat 6 | 9723 BD | F15: Groningen | G15: 17 | H15: =I14+G15/1440+0/1440 -> 0.51180556 | I15: =H15+20/1440 -> 0.52569444 | J15: Eigen lead | K15: Open adres
A16: Yasmijn + Steven | B16: 3 | C16: ONA Groep | D16: Yasmijn | E16: Nijverheidsweg 16 | 3762 ER | F16: Soest | G16: 115 | H16: =I15+G16/1440+0/1440 -> 0.60555556 | I16: =H16+20/1440 -> 0.61944444 | J16: Eigen lead | K16: Open adres
A17: Yasmijn + Steven | B17: TERUG | C17: Amsterdam Centraal | E17: Stationsplein | F17: Amsterdam | G17: 51 | H17: =I16+G17/1440+30/1440 -> 0.67569444 | I17: =H17 -> 0.67569444 | J17: Inclusief lunch van 30 min
A19: Friso + Thierry | B19: START | C19: Amsterdam Centraal | E19: Stationsplein, Amsterdam | F19: Amsterdam | G19: 0 | H19: 0.39583333 | I19: 0.39583333 | J19: Per auto; rijtijden indicatief
A20: Friso + Thierry | B20: 1 | C20: White House Scheveningen | D20: Thierry | E20: Strandweg 180 | 2586 JM | F20: Den Haag | G20: 93 | H20: =I19+G20/1440+0/1440 -> 0.46041667 | I20: =H20+20/1440 -> 0.47430556 | J20: Eigen lead | K20: Open adres
A21: Friso + Thierry | B21: 2 | C21: Paard | D21: Yasmijn | E21: Prinsegracht 12 | 2512 GA | F21: Den Haag | G21: 19 | H21: =I20+G21/1440+0/1440 -> 0.4875 | I21: =H21+20/1440 -> 0.50138889 | J21: Overgenomen van Yasmijn | K21: Open adres
A22: Friso + Thierry | B22: 3 | C22: Give Soul | D22: Friso | E22: Eendrachtsweg 42 | 3012 LD | F22: Rotterdam | G22: 37 | H22: =I21+G22/1440+0/1440 -> 0.52708333 | I22: =H22+20/1440 -> 0.54097222 | J22: Eigen lead | K22: Open adres
A23: Friso + Thierry | B23: 4 | C23: Ahoy Rotterdam | D23: Friso | E23: Ahoyweg 10 | 3084 BD | F23: Rotterdam | G23: 18 | H23: =I22+G23/1440+30/1440 -> 0.57430556 | I23: =H23+20/1440 -> 0.58819444 | J23: Eigen lead | K23: Open adres
A24: Friso + Thierry | B24: 5 | C24: Vivre Productions | D24: Friso | E24: Hoofdweg-Noord 9K | 2913 LB | F24: Nieuwekerk ad IJssel | G24: 27 | H24: =I23+G24/1440+0/1440 -> 0.60694444 | I24: =H24+20/1440 -> 0.62083333 | J24: Eigen lead | K24: Open adres
A25: Friso + Thierry | B25: TERUG | C25: Amsterdam Centraal | E25: Stationsplein | F25: Amsterdam | G25: 79 | H25: =I24+G25/1440+0/1440 -> 0.67569444 | I25: =H25 -> 0.67569444 | J25: Inclusief lunch van 30 min

Sheet Dag 2
A1: DAG 2 | VERTREK 09:30 | 20 MINUTEN PER LEAD + 30 MIN LUNCH
A2: Team | B2: Stop | C2: Lead | D2: Leadowner | E2: Adres | F2: Plaats | G2: Rijtijd vanaf vorig (min) | H2: Aankomst | I2: Vertrek | J2: Opmerking | K2: Google Maps
A3: Emiel + Bas | B3: START | C3: Amsterdam Centraal | E3: Stationsplein, Amsterdam | F3: Amsterdam | G3: 0 | H3: 0.39583333 | I3: 0.39583333 | J3: Per auto; rijtijden indicatief
A4: Emiel + Bas | B4: 1 | C4: Theater 't Kapelletje | D4: Bas | E4: Van der Sluysstraat 176 | 3033 SR | F4: Rotterdam | G4: 82 | H4: =I3+G4/1440+0/1440 -> 0.45277778 | I4: =H4+20/1440 -> 0.46666667 | J4: Eigen lead | K4: Open adres
A5: Emiel + Bas | B5: 2 | C5: CUBE | D5: Friso | E5: Slepersvest 1 | 3011 ML | F5: Rotterdam | G5: 16 | H5: =I4+G5/1440+0/1440 -> 0.47777778 | I5: =H5+20/1440 -> 0.49166667 | J5: Overgenomen van Friso | K5: Open adres
A6: Emiel + Bas | B6: 3 | C6: Cinema Culinair | D6: Yasmijn | E6: Keilestraat 9F | 3029 BP | F6: Rotterdam | G6: 17 | H6: =I5+G6/1440+0/1440 -> 0.50347222 | I6: =H6+20/1440+30/1440 -> 0.53819444 | J6: Overgenomen van Yasmijn | K6: Open adres
A7: Emiel + Bas | B7: 5 | C7: The Zoo | D7: Thierry | E7: Boonsweg 10 | 274 LH | F7: Heinenoord | G7: 30 | H7: =I6+G7/1440+30/1440 -> 0.57986111 | I7: =H7+20/1440 -> 0.59375 | J7: Overgenomen van Thierry | K7: Open adres
A8: Emiel + Bas | B8: 4 | C8: Bloemencorso | D8: Bas | E8: 1e Havendwarsstraat 4 2161 HG | F8: Lisse | G8: 86 | H8: =I7+G8/1440 -> 0.65347222 | I8: =H8+20/1440 -> 0.66736111 | J8: Eigen lead
A9: Emiel + Bas | B9: TERUG | C9: Amsterdam Centraal | E9: Stationsplein | F9: Amsterdam | G9: 47 | H9: =I8+G9/1440+0/1440 -> 0.7 | I9: =H9 -> 0.7 | J9: Inclusief lunch van 30 min
A11: Yasmijn + Steven | B11: START | C11: Amsterdam Centraal | E11: Stationsplein, Amsterdam | F11: Amsterdam | G11: 0 | H11: 0.39583333 | I11: 0.39583333 | J11: Per auto; rijtijden indicatief
A12: Yasmijn + Steven | B12: 1 | C12: Classified Events [Urgent] | D12: Thierry | E12: Oude Molenweg 112 | 6533WN | F12: Nijmegen | G12: 92 | H12: =I11+G12/1440+0/1440 -> 0.45972222 | I12: =H12+20/1440 -> 0.47361111 | J12: Overgenomen van Thierry | K12: Open adres
A13: Yasmijn + Steven | B13: 2 | C13: Studio Linksvoor | D13: Yasmijn | E13: De Kolk 13 | 6541 AV | F13: Nijmegen | G13: 14 | H13: =I12+G13/1440+0/1440 -> 0.48333333 | I13: =H13+20/1440 -> 0.49722222 | J13: Eigen lead | K13: Open adres
A14: Yasmijn + Steven | B14: 4 | C14: Muze Misse | D14: Yasmijn | E14: Sint Sebastiaanstraat 57 | 5341 LG | F14: Oss | G14: 35 | H14: =I13+G14/1440+0/1440 -> 0.52152778 | I14: =H14+20/1440 -> 0.53541667 | J14: Eigen lead | K14: Open adres
A15: Yasmijn + Steven | B15: 5 | C15: Par-t | D15: Yasmijn | E15: Bussele 17 | 5469 DT | F15: Erp/Veghel | G15: 25 | H15: =I14+G15/1440+30/1440 -> 0.57361111 | I15: =H15+20/1440 -> 0.5875 | J15: Eigen lead | K15: Open adres
A16: Yasmijn + Steven | B16: 6 | C16: Minority Events | D16: Yasmijn | E16: Dragonder 49J | 5555 XZ | F16: Valkenswaard | G16: 40 | H16: =I15+G16/1440+0/1440 -> 0.61527778 | I16: =H16+20/1440 -> 0.62916667 | J16: Eigen lead | K16: Open adres
A17: Yasmijn + Steven | B17: TERUG | C17: Amsterdam Centraal | E17: Stationsplein | F17: Amsterdam | G17: 112 | H17: =I16+G17/1440+0/1440 -> 0.70694444 | I17: =H17 -> 0.70694444 | J17: Inclusief lunch van 30 min
A19: Friso + Thierry | B19: START | C19: Amsterdam Centraal | E19: Stationsplein, Amsterdam | F19: Amsterdam | G19: 0 | H19: 0.39583333 | I19: 0.39583333 | J19: Per auto; rijtijden indicatief
A20: Friso + Thierry | B20: 1 | C20: Audio Obscura | D20: Friso | E20: Prinsengracht 769 | 1017 JZ | F20: Amsterdam | G20: 23 | H20: =I19+G20/1440+0/1440 -> 0.41180556 | I20: =H20+20/1440 -> 0.42569444 | J20: Eigen lead | K20: Open adres
A21: Friso + Thierry | B21: 2 | C21: Tropikali | D21: Friso | E21: Prinsengracht 754-3 | 1017 LD | F21: Amsterdam | G21: 4 | H21: =I20+G21/1440+0/1440 -> 0.42847222 | I21: =H21+20/1440 -> 0.44236111 | J21: Eigen lead | K21: Open adres
A22: Friso + Thierry | B22: 3 | C22: A Venue | D22: Friso | E22: Keizersgracht 618 | 1017 ER | F22: Amsterdam | G22: 5 | H22: =I21+G22/1440+0/1440 -> 0.44583333 | I22: =H22+20/1440 -> 0.45972222 | J22: Eigen lead | K22: Open adres
A23: Friso + Thierry | B23: 4 | C23: Loveland | D23: Friso | E23: Helicopterstraat 25L | 1059 CE | F23: Amsterdam | G23: 25 | H23: =I22+G23/1440+30/1440 -> 0.49791667 | I23: =H23+20/1440 -> 0.51180556 | J23: Eigen lead | K23: Open adres
A24: Friso + Thierry | B24: 5 | C24: 3X3 Basketbal | D24: Friso | E24: Keienbergweg 93 | 1101 GE | F24: Amsterdam | G24: 22 | H24: =I23+G24/1440+0/1440 -> 0.52708333 | I24: =H24+20/1440 -> 0.54097222 | J24: Eigen lead | K24: Open adres
A25: Friso + Thierry | B25: 6 | C25: Verknipt | D25: Friso | E25: Gein Zuid 9 | 1391 GT | F25: Abcoude | G25: 17 | H25: =I24+G25/1440+0/1440 -> 0.55277778 | I25: =H25+20/1440 -> 0.56666667 | J25: Eigen lead | K25: Open adres
A26: Friso + Thierry | B26: 7 | C26: 8Ball | D26: Friso | E26: ’s Gravelandseweg 80 | 1217EW | F26: Hilversum | G26: 31 | H26: =I25+G26/1440+0/1440 -> 0.58819444 | I26: =H26+20/1440 -> 0.60208333 | J26: Eigen lead | K26: Open adres
A27: Friso + Thierry | B27: TERUG | C27: Amsterdam Centraal | E27: Stationsplein | F27: Amsterdam | G27: 38 | H27: =I26+G27/1440+0/1440 -> 0.62847222 | I27: =H27 -> 0.62847222 | J27: Inclusief lunch van 30 min

Sheet Dag 3
A1: DAG 3 | VERTREK 09:30 | 20 MINUTEN PER LEAD + 30 MIN LUNCH
A2: Team | B2: Stop | C2: Lead | D2: Leadowner | E2: Adres | F2: Plaats | G2: Rijtijd vanaf vorig (min) | H2: Aankomst | I2: Vertrek | J2: Opmerking | K2: Google Maps
A3: Emiel + Bas | B3: START | C3: Amsterdam Centraal | E3: Stationsplein, Amsterdam | F3: Amsterdam | G3: 0 | H3: 0.39583333 | I3: 0.39583333 | J3: Per auto; rijtijden indicatief
A4: Emiel + Bas | B4: 1 | C4: Vault Sessions | D4: Friso | E4: Weerenweg 13 unit A | 1161 AE | F4: Zwanenburg | G4: 24 | H4: =I3+G4/1440+0/1440 -> 0.4125 | I4: =H4+20/1440 -> 0.42638889 | J4: Overgenomen van Friso | K4: Open adres
A5: Emiel + Bas | B5: 2 | C5: Making Waves | D5: Odin | E5: Doctor Jan van Breemenstraat 1 | 1056 Ab | F5: Amsterdam | G5: 18 | H5: =I4+G5/1440+0/1440 -> 0.43888889 | I5: =H5+20/1440 -> 0.45277778 | J5: Overgenomen van Odin | K5: Open adres
A6: Emiel + Bas | B6: 3 | C6: Melkweg | D6: Odin | E6: Lijnbaansgracht 234A | 1017 PH | F6: Amsterdam | G6: 15 | H6: =I5+G6/1440+0/1440 -> 0.46319444 | I6: =H6+20/1440 -> 0.47708333 | J6: Overgenomen van Odin | K6: Open adres
A7: Emiel + Bas | B7: 4 | C7: Lofi | D7: Yasmijn | E7: Basisweg 63 | 1043 AN | F7: Amsterdam | G7: 18 | H7: =I6+G7/1440+30/1440 -> 0.51041667 | I7: =H7+20/1440 -> 0.52430556 | J7: Overgenomen van Yasmijn | K7: Open adres
A8: Emiel + Bas | B8: 5 | C8: Listen to Flow | D8: Thierry | E8: Roodwilligen 63, 6903 TB | F8: Zevenaar | G8: 0.082638889 | H8: 0.60694444 | I8: 0.62083333 | J8: overgenomen van Thierry
A9: Emiel + Bas | B9: TERUG | C9: Amsterdam Centraal | E9: Stationsplein | F9: Amsterdam | G9: 0.076388889 | H9: 0.69722222 | I9: =H9 -> 0.69722222 | J9: Inclusief lunch van 30 min
A11: Yasmijn + Steven | B11: START | C11: Amsterdam Centraal | E11: Stationsplein, Amsterdam | F11: Amsterdam | G11: 0 | H11: 0.39583333 | I11: 0.39583333 | J11: Per auto; rijtijden indicatief
A12: Yasmijn + Steven | B12: 1 | C12: Volt | D12: Yasmijn | E12: Odasingel 88 | 6131 GZ | F12: Sittard | G12: 132 | H12: =I11+G12/1440+0/1440 -> 0.4875 | I12: =H12+20/1440 -> 0.50138889 | J12: Eigen lead | K12: Open adres
A13: Yasmijn + Steven | B13: 2 | C13: Elevation Events | D13: Yasmijn | E13: Leidseweg 125 | 3533 HC | F13: Utrecht | G13: 97 | H13: =I12+G13/1440+0/1440 -> 0.56875 | I13: =H13+20/1440 -> 0.58263889 | J13: Eigen lead | K13: Open adres
A14: Yasmijn + Steven | B14: 3 | C14: Jaarbeurs | D14: Thierry | E14: Jaarbeursplein 6 3521 AL | F14: Utrecht | G14: 5 | H14: =I13+G14/1440+0/1440 -> 0.58611111 | I14: 0.60069444
A15: Yasmijn + Steven | B15: 4 | C15: Intercell/ AFP | D15: Yasmijn | E15: Rokin 54 | 1012KV | F15: Amsterdam | G15: 39 | H15: =I14+G15/1440+0/1440 -> 0.62777778 | I15: =H15+20/1440 -> 0.64166667 | J15: Eigen lead | K15: Open adres
A16: Yasmijn + Steven | B16: 5 | C16: Sunsplash | D16: Yasmijn | E16: Tondenpad 9 | 1107PL | F16: Amsterdam | G16: 29 | H16: =I15+G16/1440+30/1440 -> 0.68263889 | I16: =H16+20/1440 -> 0.69652778 | J16: Eigen lead | K16: Open adres
A17: Yasmijn + Steven | B17: TERUG | C17: Amsterdam Centraal | E17: Stationsplein | F17: Amsterdam | G17: 26 | H17: =I16+G17/1440+0/1440 -> 0.71458333 | I17: =H17 -> 0.71458333 | J17: Inclusief lunch van 30 min
A19: Friso + Thierry | B19: START | C19: Amsterdam Centraal | E19: Stationsplein, Amsterdam | F19: Amsterdam | G19: 0 | H19: 0.39583333 | I19: 0.39583333 | J19: Per auto; rijtijden indicatief
A20: Friso + Thierry | B20: 1 | C20: Dfrnt Festival (Tapt) | D20: Yasmijn | E20: Dukdalfweg 38 | 1041 BE | F20: Amsterdam | G20: 22 | H20: =I19+G20/1440+0/1440 -> 0.41111111 | I20: =H20+20/1440 -> 0.425 | J20: Overgenomen van Yasmijn | K20: Open adres
A21: Friso + Thierry | B21: 2 | C21: Gashouder | D21: Yasmijn | E21: Polonceaukade 9 | 1014 DA | F21: Amsterdam | G21: 13 | H21: =I20+G21/1440+0/1440 -> 0.43402778 | I21: =H21+20/1440 -> 0.44791667 | J21: Overgenomen van Yasmijn | K21: Open adres
A22: Friso + Thierry | B22: 3 | C22: Thuishaven | D22: Friso | E22: Contactweg 68 | 1014 BW | F22: Amsterdam | G22: 9 | H22: =I21+G22/1440+0/1440 -> 0.45416667 | I22: =H22+20/1440 -> 0.46805556 | J22: Eigen lead | K22: Open adres
A23: Friso + Thierry | B23: 4 | C23: IsBurning | D23: Friso | E23: Elementenstraat 25 | 1014 AS | F23: Amsterdam | G23: 10 | H23: =I22+G23/1440+30/1440 -> 0.49583333 | I23: =H23+20/1440 -> 0.50972222 | J23: Eigen lead | K23: Open adres
A24: Friso + Thierry | B24: 5 | C24: VBX | D24: Friso | E24: Krelis Louwenstraat 1 | 1055 KA | F24: Amsterdam | G24: 14 | H24: =I23+G24/1440+0/1440 -> 0.51944444 | I24: =H24+20/1440 -> 0.53333333 | J24: Eigen lead | K24: Open adres
A25: Friso + Thierry | B25: 6 | C25: Woodstock | D25: Thierry | E25: Zeeweg 94, tent 7 (BL10) | 2051 EC | F25: Bloemendaal aan Zee | G25: 36 | H25: =I24+G25/1440+0/1440 -> 0.55833333 | I25: =H25+20/1440 -> 0.57222222 | J25: Eigen lead | K25: Open adres
A26: Friso + Thierry | B26: TERUG | C26: Amsterdam Centraal | E26: Stationsplein | F26: Amsterdam | G26: 44 | H26: =I25+G26/1440+0/1440 -> 0.60277778 | I26: =H26 -> 0.60277778 | J26: Inclusief lunch van 30 min

Sheet Adressen controleren
A1: Lead | B1: Leadowner | C1: Huidige informatie | D1: Waarom niet ingepland | E1: Actie
A2: (vrienden van) Bloemencorso Bollenstreek | B2: Bas | C2: Postbus 115, 2160 AC Lisse | D2: Postbus, geen afleverlocatie | E2: Vraag fysiek bezoekadres op; Emiel + Bas dag 3 indien haalbaar
A3: Jaarbeurs | B3: Thierry | C3: Geen adres ingevuld | D3: Specifieke afleverlocatie ontbreekt | E3: Adres/ingang bevestigen; eventueel Yasmijn + Steven dag 3 Utrecht
A4: Listen to Flow | B4: Thierry | C4: Geen adres ingevuld | D4: Geen locatie bekend | E4: Adres opvragen en koppelen aan passende regionale route
A5: Poppodium Volt | B5: Thierry | C5: Staat er al in | D5: Dubbel van Volt, Odasingel 88, Sittard | E5: Slechts eenmaal ingepland: Yasmijn + Steven dag 3
A7: Belangrijke aannames
A8: Alle teams rijden dagelijks vanaf Amsterdam Centraal en keren daar terug.
A9: Elke lead: 20 minuten op locatie. Lunch: 30 minuten na de vierde stop (of op de terugreis bij routes met maximaal drie stops).
A10: Rijtijden zijn grove planningsschattingen en niet uit een live routeplanner; parkeren, binnenstad en verkeersdrukte kunnen afwijken.
A11: Alleen de expliciete koppeling Emiel + Bas en hun eigen leads geldt als harde eis. Overige eigen-leadbezoeken zijn waar praktisch behouden.
A12: Controleer ontvangsttijden, fysieke kantoren en exacte ingangen vóór vertrek.
A13: Planning heeft reserve, maar geen expliciete aparte parkeerminuten per bezoek.

Sheet Sheet1
A1: Toekomst Muziek B.V. | B1: Bas
A2: Torpedotheater | B2: Bas
A3: Bijlmerbios Openluchtbioscoop | B3: Emiel
A4: Theater 't Kapelletje | B4: Bas
A5: Bloemencorso | B5: Bas
A6: Supper Club | B6: Bas
